Workbook

Sheet DATOS
A3: Fecha
A4: Proyecto
A5: Documento patrón | D5: Memoria de Cálculo
A6: Codigo de documento patrón
A7: Nombre de anexo
A8: Revision
H14: df

Sheet H55
B2: Memoria de cálculo | F2: =DATOS!D6 -> 0 | L2: =DATOS!D7 -> 0
L3: =DATOS!D8 -> 0
B6: Muro | C6: 5.5
B27: 1. CARACTERÍSTICAS GEOMÉTRICAS DEL MURO
B28: H= | C28: =+C31+C32+C30 -> 6.15 | D28: m | E28: Altura total del muro
B29: Hp= | C29: =C31+C30 -> 5.5 | D29: m | E29: Altura de la pantalla
B30: hc= | C30: 0 | D30: m | E30: Altura corona
B31: Hr= | C31: =+C6 -> 5.5 | D31: m | E31: Altura del suelo de relleno | R31: RECOMENDACIONES PARA DIMENSIONAR LA ZAPATA
B32: Hz= | C32: 0.65 | D32: m | E32: Altura de la zapata | R32: Recomendado | T32: Min / ref. | U32: Max / ref.
Q33: Hz=
B34: B1= | C34: 1 | D34: m | E34: Punta | Q34: B1= | R34: B/4 a B/3 = | T34: =C37/4 -> 0.925 | U34: =C37/3 -> 1.2333333
B35: B2= | C35: 0.1 | D35: m | E35: Pantalla | Q35: B3= | R35: B-b1-b2= | T35: - | U35: =2*U34 -> 2.4666667
B36: B3= | C36: 2.6 | D36: m | E36: Talón | Q36: B= | R36: 0.4H a 0.7H = | T36: =0.4*C28 -> 2.46 | U36: =0.7*C28 -> 4.305
B37: B= | C37: =C34+C35+C36 -> 3.7 | D37: m | E37: Base
B38: N° | C38: 2 | E38: Número de contrafuertes por módulo
B39: L | C39: 2.4 | E39: Longitud del módulo
B40: Contrafuerte | D40: Tipo : | E40: Cc6
B41: a | C41: =VLOOKUP($E$40,'Base de datos '!$A$3:$H$18,2,FALSE) -> 0.33 | D41: m
B42: b | C42: =VLOOKUP($E$40,'Base de datos '!$A$3:$H$18,3,FALSE) -> 1.24 | D42: m
B43: c | C43: =VLOOKUP($E$40,'Base de datos '!$A$3:$H$18,4,FALSE) -> 1.5 | D43: m
B44: d | C44: =VLOOKUP($E$40,'Base de datos '!$A$3:$H$18,5,FALSE) -> 3 | D44: m
B45: e | C45: =VLOOKUP($E$40,'Base de datos '!$A$3:$H$18,6,FALSE) -> 0.126
B46: f | C46: =VLOOKUP($E$40,'Base de datos '!$A$3:$H$18,7,FALSE) -> 0.24
B47: g | C47: =VLOOKUP($E$40,'Base de datos '!$A$3:$H$18,8,FALSE) -> 0.519 | D47: m
B48: k | C48: 0.1 | D48: m | E48: Espesor del contrafuerte
B50: 2. PARÁMETROS DE DISEÑO
B51: 2.1 Propiedades de los materiales
B52: Фr | C52: 35 | D52: ° | E52: Ángulo de fricción interna del suelo que empuja
B53: Фf | C53: 35 | D53: ° | E53: Ángulo de fricción interna del suelo de fundación
B54: d= | C54: =2*C52/3 -> 23.333333 | D54: ° | E54: Ángulo de fricción entre el muro y relleno AASHTO 3.11.5.3-1
B55: gr= | C55: 1.8 | D55: T/m3 | E55: Peso específico del relleno
B56: gc= | C56: 2.5 | D56: T/m3 | E56: Peso específico del concreto
B57: b= | C57: 0 | D57: ° | E57: Ángulo de inclinación de la suerperficie de relleno
B58: q= | C58: 90 | D58: ° | E58: Ángulo de inclinación del muro del lado del terreno
B59: qULT | C59: =2.5*3 -> 7.5 | D59: Kg/cm2 | E59: Capacidad ultima del suelo de fundación
B61: 2.2 Parámetros sísmicos y sobrecarga vehicular
B62: A= | C62: 0.45 | E62: Coeficiente de Aceleración PGA, en la base. Ver 11.6.5.2.1.
B63: Heq = | C63: 0.6 | D63: m | E63: Sobrecarga vehicular AASHTO 3.11.6.4
B65: 3. CALCULO DE CARGAS DE DISEÑO
B66: 3.1. EMPUJE LATERAL DEL TERRENO
...

Sheet Base de datos 
A1: Contrafuertes Estándar
A3: CF | B3: a | C3: b | D3: c | E3: d | F3: e | G3: f | H3: g
A4: Sin contrafuerte | B4: 0 | C4: 0 | D4: 0 | E4: 0.0001 | F4: 0 | G4: 0 | H4: 0.0001
A5: Cc3 | B5: 0.43 | C5: 0.67 | D5: 1.5 | E5: 0 | F5: 0.155 | G5: 0 | H5: =F5*D5+B5 -> 0.6625
A6: Cb3 | B6: 0.36 | C6: 0.67 | D6: 2 | E6: 0 | F6: 0.155 | G6: 0 | H6: =F6*D6+B6 -> 0.67
A7: Cc4 | B7: 0.433 | C7: 0.82 | D7: 2.5 | E7: 0 | F7: 0.155 | G7: 0 | H7: =F7*D7+B7 -> 0.8205
A8: Cb4 | B8: 0.356 | C8: 0.82 | D8: 3 | E8: 0 | F8: 0.155 | G8: 0 | H8: =F8*D8+B8 -> 0.821
A9: Cc5 | B9: 0.33 | C9: 1 | D9: 1.5 | E9: 2 | F9: 0.126 | G9: 0.24 | H9: =F9*D9+B9 -> 0.519
A10: Cb5 | B10: 0.26 | C10: 1 | D10: 2 | E10: 2 | F10: 0.126 | G10: 0.24 | H10: =F10*D10+B10 -> 0.512
A11: Cc6 | B11: 0.33 | C11: 1.24 | D11: 1.5 | E11: 3 | F11: 0.126 | G11: 0.24 | H11: =F11*D11+B11 -> 0.519
A12: Cb6 | B12: 0.26 | C12: 1.24 | D12: 2 | E12: 3 | F12: 0.126 | G12: 0.24 | H12: =F12*D12+B12 -> 0.512
A13: Cc7 | B13: 0.33 | C13: 1.48 | D13: 1.5 | E13: 4 | F13: 0.126 | G13: 0.24 | H13: =F13*D13+B13 -> 0.519
A14: Cb7 | B14: 0.26 | C14: 1.48 | D14: 2 | E14: 4 | F14: 0.126 | G14: 0.24 | H14: =F14*D14+B14 -> 0.512
A15: Cc8 | B15: 0.33 | C15: 1.72 | D15: 1.5 | E15: 5 | F15: 0.126 | G15: 0.24 | H15: =F15*D15+B15 -> 0.519
A16: Cb8 | B16: 0.26 | C16: 1.72 | D16: 2 | E16: 5 | F16: 0.126 | G16: 0.24 | H16: =F16*D16+B16 -> 0.512
A17: Ca8 | B17: 0.2 | C17: 1.72 | D17: 2.5 | E17: 5 | F17: 0.126 | G17: 0.24 | H17: =F17*D17+B17 -> 0.515

Sheet Ayuda de diseño 
B2: RECOMENDACIONES DE DIMENSIONAMIENTO | H2: PUENTES Y OBRAS DE ARTE Ing. Arturo Rodríguez Serquén | P2: 3.11.5.3—Active Lateral Earth Pressure
P3: Coefficient, k
S4: a
B32: AASHTO3.11.6.4: Altura equivalente de suelo por carga vehicular en muros

Sheet Resumen
A2: Ubicación de las celdas de coordenadas
B3: 15 | C3: 20 | D3: 25 | E3: 30 | F3: 35 | G3: 40 | H3: 45 | I3: 50 | J3: 55 | K3: 60 | L3: 65 | M3: 70 | N3: 75 | O3: 80 | P3: 85 | Q3: 90 | R3: 95 | S3: 100 | T3: 105
A4: 470 | B4: ="H"&B$3&"!"&"M"&$A4 -> H15!M470 | C4: ="H"&C$3&"!"&"M"&$A4 -> H20!M470 | D4: ="H"&D$3&"!"&"M"&$A4 -> H25!M470 | E4: ="H"&E$3&"!"&"M"&$A4 -> H30!M470 | F4: ="H"&F$3&"!"&"M"&$A4 -> H35!M470 | G4: ="H"&G$3&"!"&"M"&$A4 -> H40!M470 | H4: ="H"&H$3&"!"&"M"&$A4 -> H45!M470 | I4: ="H"&I$3&"!"&"M"&$A4 -> H50!M470 | ... T4: ="H"&T$3&"!"&"M"&$A4 -> H105!M470
A5: 471 | B5: ="H"&B$3&"!"&"M"&$A5 -> H15!M471 | C5: ="H"&C$3&"!"&"M"&$A5 -> H20!M471 | D5: ="H"&D$3&"!"&"M"&$A5 -> H25!M471 | E5: ="H"&E$3&"!"&"M"&$A5 -> H30!M471 | F5: ="H"&F$3&"!"&"M"&$A5 -> H35!M471 | G5: ="H"&G$3&"!"&"M"&$A5 -> H40!M471 | H5: ="H"&H$3&"!"&"M"&$A5 -> H45!M471 | I5: ="H"&I$3&"!"&"M"&$A5 -> H50!M471 | ... T5: ="H"&T$3&"!"&"M"&$A5 -> H105!M471
A6: 472 | B6: ="H"&B$3&"!"&"M"&$A6 -> H15!M472 | C6: ="H"&C$3&"!"&"M"&$A6 -> H20!M472 | D6: ="H"&D$3&"!"&"M"&$A6 -> H25!M472 | E6: ="H"&E$3&"!"&"M"&$A6 -> H30!M472 | F6: ="H"&F$3&"!"&"M"&$A6 -> H35!M472 | G6: ="H"&G$3&"!"&"M"&$A6 -> H40!M472 | H6: ="H"&H$3&"!"&"M"&$A6 -> H45!M472 | I6: ="H"&I$3&"!"&"M"&$A6 -> H50!M472 | ... T6: ="H"&T$3&"!"&"M"&$A6 -> H105!M472
A7: 473 | B7: ="H"&B$3&"!"&"M"&$A7 -> H15!M473 | C7: ="H"&C$3&"!"&"M"&$A7 -> H20!M473 | D7: ="H"&D$3&"!"&"M"&$A7 -> H25!M473 | E7: ="H"&E$3&"!"&"M"&$A7 -> H30!M473 | F7: ="H"&F$3&"!"&"M"&$A7 -> H35!M473 | G7: ="H"&G$3&"!"&"M"&$A7 -> H40!M473 | H7: ="H"&H$3&"!"&"M"&$A7 -> H45!M473 | I7: ="H"&I$3&"!"&"M"&$A7 -> H50!M473 | ... T7: ="H"&T$3&"!"&"M"&$A7 -> H105!M473
A8: 474 | B8: ="H"&B$3&"!"&"M"&$A8 -> H15!M474 | C8: ="H"&C$3&"!"&"M"&$A8 -> H20!M474 | D8: ="H"&D$3&"!"&"M"&$A8 -> H25!M474 | E8: ="H"&E$3&"!"&"M"&$A8 -> H30!M474 | F8: ="H"&F$3&"!"&"M"&$A8 -> H35!M474 | G8: ="H"&G$3&"!"&"M"&$A8 -> H40!M474 | H8: ="H"&H$3&"!"&"M"&$A8 -> H45!M474 | I8: ="H"&I$3&"!"&"M"&$A8 -> H50!M474 | ... T8: ="H"&T$3&"!"&"M"&$A8 -> H105!M474
A9: 475 | B9: ="H"&B$3&"!"&"M"&$A9 -> H15!M475 | C9: ="H"&C$3&"!"&"M"&$A9 -> H20!M475 | D9: ="H"&D$3&"!"&"M"&$A9 -> H25!M475 | E9: ="H"&E$3&"!"&"M"&$A9 -> H30!M475 | F9: ="H"&F$3&"!"&"M"&$A9 -> H35!M475 | G9: ="H"&G$3&"!"&"M"&$A9 -> H40!M475 | H9: ="H"&H$3&"!"&"M"&$A9 -> H45!M475 | I9: ="H"&I$3&"!"&"M"&$A9 -> H50!M475 | ... T9: ="H"&T$3&"!"&"M"&$A9 -> H105!M475
A10: 476 | B10: ="H"&B$3&"!"&"M"&$A10 -> H15!M476 | C10: ="H"&C$3&"!"&"M"&$A10 -> H20!M476 | D10: ="H"&D$3&"!"&"M"&$A10 -> H25!M476 | E10: ="H"&E$3&"!"&"M"&$A10 -> H30!M476 | F10: ="H"&F$3&"!"&"M"&$A10 -> H35!M476 | G10: ="H"&G$3&"!"&"M"&$A10 -> H40!M476 | H10: ="H"&H$3&"!"&"M"&$A10 -> H45!M476 | I10: ="H"&I$3&"!"&"M"&$A10 -> H50!M476 | ... T10: ="H"&T$3&"!"&"M"&$A10 -> H105!M476
A11: 477 | B11: ="H"&B$3&"!"&"M"&$A11 -> H15!M477 | C11: ="H"&C$3&"!"&"M"&$A11 -> H20!M477 | D11: ="H"&D$3&"!"&"M"&$A11 -> H25!M477 | E11: ="H"&E$3&"!"&"M"&$A11 -> H30!M477 | F11: ="H"&F$3&"!"&"M"&$A11 -> H35!M477 | G11: ="H"&G$3&"!"&"M"&$A11 -> H40!M477 | H11: ="H"&H$3&"!"&"M"&$A11 -> H45!M477 | I11: ="H"&I$3&"!"&"M"&$A11 -> H50!M477 | ... T11: ="H"&T$3&"!"&"M"&$A11 -> H105!M477
A12: 478 | B12: ="H"&B$3&"!"&"M"&$A12 -> H15!M478 | C12: ="H"&C$3&"!"&"M"&$A12 -> H20!M478 | D12: ="H"&D$3&"!"&"M"&$A12 -> H25!M478 | E12: ="H"&E$3&"!"&"M"&$A12 -> H30!M478 | F12: ="H"&F$3&"!"&"M"&$A12 -> H35!M478 | G12: ="H"&G$3&"!"&"M"&$A12 -> H40!M478 | H12: ="H"&H$3&"!"&"M"&$A12 -> H45!M478 | I12: ="H"&I$3&"!"&"M"&$A12 -> H50!M478 | ... T12: ="H"&T$3&"!"&"M"&$A12 -> H105!M478
A13: 479 | B13: ="H"&B$3&"!"&"M"&$A13 -> H15!M479 | C13: ="H"&C$3&"!"&"M"&$A13 -> H20!M479 | D13: ="H"&D$3&"!"&"M"&$A13 -> H25!M479 | E13: ="H"&E$3&"!"&"M"&$A13 -> H30!M479 | F13: ="H"&F$3&"!"&"M"&$A13 -> H35!M479 | G13: ="H"&G$3&"!"&"M"&$A13 -> H40!M479 | H13: ="H"&H$3&"!"&"M"&$A13 -> H45!M479 | I13: ="H"&I$3&"!"&"M"&$A13 -> H50!M479 | ... T13: ="H"&T$3&"!"&"M"&$A13 -> H105!M479
A14: 480 | B14: ="H"&B$3&"!"&"M"&$A14 -> H15!M480 | C14: ="H"&C$3&"!"&"M"&$A14 -> H20!M480 | D14: ="H"&D$3&"!"&"M"&$A14 -> H25!M480 | E14: ="H"&E$3&"!"&"M"&$A14 -> H30!M480 | F14: ="H"&F$3&"!"&"M"&$A14 -> H35!M480 | G14: ="H"&G$3&"!"&"M"&$A14 -> H40!M480 | H14: ="H"&H$3&"!"&"M"&$A14 -> H45!M480 | I14: ="H"&I$3&"!"&"M"&$A14 -> H50!M480 | ... T14: ="H"&T$3&"!"&"M"&$A14 -> H105!M480
A15: 481 | B15: ="H"&B$3&"!"&"M"&$A15 -> H15!M481 | C15: ="H"&C$3&"!"&"M"&$A15 -> H20!M481 | D15: ="H"&D$3&"!"&"M"&$A15 -> H25!M481 | E15: ="H"&E$3&"!"&"M"&$A15 -> H30!M481 | F15: ="H"&F$3&"!"&"M"&$A15 -> H35!M481 | G15: ="H"&G$3&"!"&"M"&$A15 -> H40!M481 | H15: ="H"&H$3&"!"&"M"&$A15 -> H45!M481 | I15: ="H"&I$3&"!"&"M"&$A15 -> H50!M481 | ... T15: ="H"&T$3&"!"&"M"&$A15 -> H105!M481
A17: Dibujo de todos los muros
B18: =INDIRECT(B4) -> #REF!
B19: =INDIRECT(B5) -> #REF!
B20: =INDIRECT(B6) -> #REF!
B21: =INDIRECT(B7) -> #REF!
B22: =INDIRECT(B8) -> #REF!
B23: =INDIRECT(B9) -> #REF!
B24: =INDIRECT(B10) -> #REF!
B25: =INDIRECT(B11) -> #REF!
B26: =INDIRECT(B12) -> #REF!
B27: =INDIRECT(B13) -> #REF!
B28: =INDIRECT(B14) -> #REF!
B29: =INDIRECT(B15) -> #REF!
B30: =INDIRECT(C4) -> #REF!
B31: =INDIRECT(C5) -> #REF!
B32: =INDIRECT(C6) -> #REF!
B33: =INDIRECT(C7) -> #REF!
B34: =INDIRECT(C8) -> #REF!
B35: =INDIRECT(C9) -> #REF!
B36: =INDIRECT(C10) -> #REF!
B37: =INDIRECT(C11) -> #REF!
B38: =INDIRECT(C12) -> #REF!
B39: =INDIRECT(C13) -> #REF!
B40: =INDIRECT(C14) -> #REF!
B41: =INDIRECT(C15) -> #REF!
B42: =INDIRECT(D4) -> #REF!
...

Sheet MetArmadura
C2: Diametro(pulg) | D2: Spaciamiento (m)
B3: Armadura de muros | AL3: Uña | AX3: m3/m | AY3: m3/m
B4: 1 | C4: 2 | D4: 3 | E4: 4 | F4: 5 | G4: 6 | H4: 7 | I4: 8 | J4: 9 | K4: 10 | L4: 11 | M4: 12 | N4: 13 | O4: 14 | P4: 15 | Q4: 16 | R4: 17 | S4: 18 | T4: 19 | U4: 20 | V4: 21 | W4: 22 | X4: 23 | Z4: CF | AL4: 37 | AM4: 38 | AN4: 39 | AO4: 40 | AQ4: Dimensiones de Uña | AX4: Zapata | AY4: Pantalla
B5: H | C5: 1 | E5: 2 | G5: 3 | I5: 4 | K5: 5 | M5: 6 | O5: 7 | Q5: 8 | S5: 9 | U5: 10 | W5: 11 | Z5: L1 | AA5: L2 | AB5: Lg | AC5: L5 | AD5: L7 | AF5: h0 | AG5: B1 | AH5: B2 | AI5: B3 | AJ5: Corona | AL5: 12 | AN5: 13 | AQ5: Bmayor | AR5: Bmenor | AS5: h | AT5: Area | AU5: Si/No | AX5: =AF7*(AG7+AH7+AI7)*1 -> #REF! | AY5: =AJ7*B7*1 -> #REF!
B6: 1.5 | C6: =INDIRECT("H"&B6*10&"!"&"E313") -> #REF! | D6: =INDIRECT("H"&B6*10&"!"&"F313") -> #REF! | E6: =INDIRECT("H"&B6*10&"!"&"E312") -> #REF! | F6: =INDIRECT("H"&B6*10&"!"&"F312") -> #REF! | G6: =INDIRECT("H"&B6*10&"!"&"E341") -> #REF! | H6: =INDIRECT("H"&B6*10&"!"&"H341") -> #REF! | I6: =INDIRECT("H"&B6*10&"!"&"E373") -> #REF! | J6: =INDIRECT("H"&B6*10&"!"&"F373") -> #REF! | K6: =INDIRECT("H"&B6*10&"!"&"E372") -> #REF! | L6: =INDIRECT("H"&B6*10&"!"&"F372") -> #REF! | M6: =INDIRECT("H"&B6*10&"!"&"E439") -> #REF! | N6: =INDIRECT("H"&B6*10&"!"&"F439") -> #REF! | O6: =INDIRECT("H"&B6*10&"!"&"E438") -> #REF! | P6: =INDIRECT("H"&B6*10&"!"&"F438") -> #REF! | Q6: =+G6 -> #REF! | R6: =+H6 -> #REF! | S6: =+Q6 -> #REF! | T6: =+R6 -> #REF! | U6: =INDIRECT("H"&B6*10&"!"&"E465") -> #REF! | V6: =INDIRECT("H"&B6*10&"!"&"h465") -> #REF! | W6: =+U6 -> #REF! | X6: =+V6 -> #REF! | Z6: =IF(INDIRECT("H"&B6*10&"!"&"G312")=0,0,INDIRECT("H"&B6*10&"!"&"G312")+VLOOKUP(E6,$AG$54:$AM$59,7,0)) -> #REF! | AA6: =CEILING(12*2.54*C6,5)/100 -> #REF! | AB6: =+AF6-(0.075+(C6*2.54/2)/100) -> #REF! | AC6: =IF(INDIRECT("H"&B6*10&"!"&"G372")=0,0,INDIRECT("H"&B6*10&"!"&"G372")+2*VLOOKUP(K6,$AG$54:$AM$59,7,0)) -> #REF! | AD6: =IF(INDIRECT("H"&B6*10&"!"&"G438")=0,0,INDIRECT("H"&B6*10&"!"&"G438")+2*VLOOKUP(O6,$AG$54:$AM$59,7,0)) -> #REF! | AF6: =INDIRECT("H"&B6*10&"!"&"C30") -> #REF! | AG6: =INDIRECT("H"&B6*10&"!"&"C32") -> #REF! | AH6: =INDIRECT("H"&B6*10&"!"&"C33") -> #REF! | AI6: =INDIRECT("H"&B6*10&"!"&"C34") -> #REF! | AJ6: =INDIRECT("H"&B6*10&"!"&"C31") -> #REF! | AL6: =INDIRECT("H"&B6*10&"!"&"T207") -> #REF! | AM6: =INDIRECT("H"&B6*10&"!"&"U207") -> #REF! | AN6: =INDIRECT("H"&B6*10&"!"&"AC207") -> #REF! | AO6: =INDIRECT("H"&B6*10&"!"&"AF207") -> #REF! | AQ6: =INDIRECT("H"&B6*10&"!"&"s195") -> #REF! | AR6: =INDIRECT("H"&B6*10&"!"&"T195") -> #REF! | AS6: =INDIRECT("H"&B6*10&"!"&"U195") -> #REF! | AT6: =AS6*(AQ6+AR6)/2 -> #REF! | AU6: =IF(INDIRECT("H"&B6*10&"!"&"L194")=" No requiere dentellon!!",0,1) -> #REF! | AX6: =AF8*(AG8+AH8+AI8)*1 -> #REF! | AY6: =AJ8*B8*1 -> #REF!
B7: =B6+0.5 -> 2 | C7: 0.375 | D7: 0.25 | E7: 0.375 | F7: 3 | G7: 0.375 | H7: 0.15 | I7: 0.375 | J7: 0.2 | K7: 0 | L7: 0 | M7: 0.375 | N7: 0.2 | O7: 0.375 | P7: 0.15 | Q7: 0.375 | R7: 0.225 | S7: 0.375 | T7: 0.125 | U7: 0.375 | V7: 0.2 | W7: 0.375 | X7: 0.2 | Z7: =CEILING(12*2.54*E7,5)/100 -> 0.15 | AA7: =CEILING(12*2.54*C7,5)/100 -> 0.15 | AB7: =IF((4*(C7*2.54)/100)<0.065,0.065,(4*(C7*2.54)/100)) -> 0.065 | AC7: =IF(K7=0,0,(VLOOKUP(K7,$AG$54:$AM$59,7,0)+AG7)) -> 0 | AD7: =CEILING(12*2.54*G7,5)/100 -> 0.15 | AF7: =INDIRECT("H"&B7*10&"!"&"C30") -> #REF! | AG7: =INDIRECT("H"&B7*10&"!"&"C32") -> #REF! | AH7: =INDIRECT("H"&B7*10&"!"&"C33") -> #REF! | AI7: =INDIRECT("H"&B7*10&"!"&"C34") -> #REF! | AJ7: =INDIRECT("H"&B7*10&"!"&"C31") -> #REF! | AL7: =INDIRECT("H"&B7*10&"!"&"T207") -> #REF! | AM7: =INDIRECT("H"&B7*10&"!"&"U207") -> #REF! | AN7: =INDIRECT("H"&B7*10&"!"&"AC207") -> #REF! | AO7: =INDIRECT("H"&B7*10&"!"&"AF207") -> #REF! | AQ7: =INDIRECT("H"&B7*10&"!"&"s195") -> #REF! | AR7: =INDIRECT("H"&B7*10&"!"&"T195") -> #REF! | AS7: =INDIRECT("H"&B7*10&"!"&"U195") -> #REF! | AT7: =AS7*(AQ7+AR7)/2 -> #REF! | AU7: =IF(INDIRECT("H"&B7*10&"!"&"L194")=" No requiere dentellon!!",0,1) -> #REF! | AX7: =AF9*(AG9+AH9+AI9)*1 -> #REF! | AY7: =AJ9*B9*1 -> #REF!
B8: =B7+0.5 -> 2.5 | C8: 0.375 | D8: 0.25 | E8: 0.375 | F8: 3 | G8: 0.375 | H8: 0.2 | I8: 0.375 | J8: 0.2 | K8: 0 | L8: 0 | M8: 0.375 | N8: 0.2 | O8: 0.375 | P8: 0.2 | Q8: 0.375 | R8: 0.225 | S8: 0.375 | T8: 0.125 | U8: 0.375 | V8: 0.2 | W8: 0.375 | X8: 0.2 | Z8: =CEILING(12*2.54*E8,5)/100 -> 0.15 | AA8: =CEILING(12*2.54*C8,5)/100 -> 0.15 | AB8: =IF((4*(C8*2.54)/100)<0.065,0.065,(4*(C8*2.54)/100)) -> 0.065 | AC8: =IF(K8=0,0,(VLOOKUP(K8,$AG$54:$AM$59,7,0)+AG8)) -> 0 | AD8: =CEILING(12*2.54*G8,5)/100 -> 0.15 | AF8: =INDIRECT("H"&B8*10&"!"&"C30") -> #REF! | AG8: =INDIRECT("H"&B8*10&"!"&"C32") -> #REF! | AH8: =INDIRECT("H"&B8*10&"!"&"C33") -> #REF! | AI8: =INDIRECT("H"&B8*10&"!"&"C34") -> #REF! | AJ8: =INDIRECT("H"&B8*10&"!"&"C31") -> #REF! | AL8: =INDIRECT("H"&B8*10&"!"&"T207") -> #REF! | AM8: =INDIRECT("H"&B8*10&"!"&"U207") -> #REF! | AN8: =INDIRECT("H"&B8*10&"!"&"AC207") -> #REF! | AO8: =INDIRECT("H"&B8*10&"!"&"AF207") -> #REF! | AQ8: =INDIRECT("H"&B8*10&"!"&"s195") -> #REF! | AR8: =INDIRECT("H"&B8*10&"!"&"T195") -> #REF! | AS8: =INDIRECT("H"&B8*10&"!"&"U195") -> #REF! | AT8: =AS8*(AQ8+AR8)/2 -> #REF! | AU8: =IF(INDIRECT("H"&B8*10&"!"&"L194")=" No requiere dentellon!!",0,1) -> #REF! | AX8: =AF10*(AG10+AH10+AI10)*1 -> #REF! | AY8: =AJ10*B10*1 -> #REF!
B9: =B8+0.5 -> 3 | C9: 0.375 | D9: 0.25 | E9: 0.5 | F9: 3 | G9: 0.5 | H9: 0.25 | I9: 0.5 | J9: 0.3 | K9: 0 | L9: 0 | M9: 0.5 | N9: 0.3 | O9: 0.5 | P9: 0.25 | Q9: 0.375 | R9: 0.225 | S9: 0.375 | T9: 0.125 | U9: 0.5 | V9: 0.3 | W9: 0.5 | X9: 0.3 | Z9: =CEILING(12*2.54*E9,5)/100 -> 0.2 | AA9: =CEILING(12*2.54*C9,5)/100 -> 0.15 | AB9: =IF((4*(C9*2.54)/100)<0.065,0.065,(4*(C9*2.54)/100)) -> 0.065 | AC9: =IF(K9=0,0,(VLOOKUP(K9,$AG$54:$AM$59,7,0)+AG9)) -> 0 | AD9: =CEILING(12*2.54*G9,5)/100 -> 0.2 | AF9: =INDIRECT("H"&B9*10&"!"&"C30") -> #REF! | AG9: =INDIRECT("H"&B9*10&"!"&"C32") -> #REF! | AH9: =INDIRECT("H"&B9*10&"!"&"C33") -> #REF! | AI9: =INDIRECT("H"&B9*10&"!"&"C34") -> #REF! | AJ9: =INDIRECT("H"&B9*10&"!"&"C31") -> #REF! | AL9: =INDIRECT("H"&B9*10&"!"&"T207") -> #REF! | AM9: =INDIRECT("H"&B9*10&"!"&"U207") -> #REF! | AN9: =INDIRECT("H"&B9*10&"!"&"AC207") -> #REF! | AO9: =INDIRECT("H"&B9*10&"!"&"AF207") -> #REF! | AQ9: =INDIRECT("H"&B9*10&"!"&"s195") -> #REF! | AR9: =INDIRECT("H"&B9*10&"!"&"T195") -> #REF! | AS9: =INDIRECT("H"&B9*10&"!"&"U195") -> #REF! | AT9: =AS9*(AQ9+AR9)/2 -> #REF! | AU9: =IF(INDIRECT("H"&B9*10&"!"&"L194")=" No requiere dentellon!!",0,1) -> #REF! | AX9: =AF11*(AG11+AH11+AI11)*1 -> #REF! | AY9: =AJ11*B11*1 -> #REF!
B10: =B9+0.5 -> 3.5 | C10: 0.375 | D10: 0.25 | E10: 0.5 | F10: 3 | G10: 0.5 | H10: 0.25 | I10: 0.5 | J10: 0.3 | K10: 0 | L10: 0 | M10: 0.5 | N10: 0.3 | O10: 0.5 | P10: 0.25 | Q10: 0.375 | R10: 0.225 | S10: 0.375 | T10: 0.125 | U10: 0.5 | V10: 0.3 | W10: 0.5 | X10: 0.3 | Z10: =CEILING(12*2.54*E10,5)/100 -> 0.2 | AA10: =CEILING(12*2.54*C10,5)/100 -> 0.15 | AB10: =IF((4*(C10*2.54)/100)<0.065,0.065,(4*(C10*2.54)/100)) -> 0.065 | AC10: =IF(K10=0,0,(VLOOKUP(K10,$AG$54:$AM$59,7,0)+AG10)) -> 0 | AD10: =CEILING(12*2.54*G10,5)/100 -> 0.2 | AF10: =INDIRECT("H"&B10*10&"!"&"C30") -> #REF! | AG10: =INDIRECT("H"&B10*10&"!"&"C32") -> #REF! | AH10: =INDIRECT("H"&B10*10&"!"&"C33") -> #REF! | AI10: =INDIRECT("H"&B10*10&"!"&"C34") -> #REF! | AJ10: =INDIRECT("H"&B10*10&"!"&"C31") -> #REF! | AL10: =INDIRECT("H"&B10*10&"!"&"T207") -> #REF! | AM10: =INDIRECT("H"&B10*10&"!"&"U207") -> #REF! | AN10: =INDIRECT("H"&B10*10&"!"&"AC207") -> #REF! | AO10: =INDIRECT("H"&B10*10&"!"&"AF207") -> #REF! | AQ10: =INDIRECT("H"&B10*10&"!"&"s195") -> #REF! | AR10: =INDIRECT("H"&B10*10&"!"&"T195") -> #REF! | AS10: =INDIRECT("H"&B10*10&"!"&"U195") -> #REF! | AT10: =AS10*(AQ10+AR10)/2 -> #REF! | AU10: =IF(INDIRECT("H"&B10*10&"!"&"L194")=" No requiere dentellon!!",0,1) -> #REF! | AX10: =AF12*(AG12+AH12+AI12)*1 -> #REF! | AY10: =AJ12*B12*1 -> #REF!
B11: =B10+0.5 -> 4 | C11: 0.375 | D11: 0.25 | E11: 0.5 | F11: 4 | G11: 0.5 | H11: 0.225 | I11: 0.5 | J11: 0.25 | K11: 0 | L11: 0 | M11: 0.5 | N11: 0.25 | O11: 0.5 | P11: 0.225 | Q11: 0.375 | R11: 0.225 | S11: 0.375 | T11: 0.125 | U11: 0.5 | V11: 0.25 | W11: 0.5 | X11: 0.25 | Z11: =CEILING(12*2.54*E11,5)/100 -> 0.2 | AA11: =CEILING(12*2.54*C11,5)/100 -> 0.15 | AB11: =IF((4*(C11*2.54)/100)<0.065,0.065,(4*(C11*2.54)/100)) -> 0.065 | AC11: =IF(K11=0,0,(VLOOKUP(K11,$AG$54:$AM$59,7,0)+AG11)) -> 0 | AD11: =CEILING(12*2.54*G11,5)/100 -> 0.2 | AF11: =INDIRECT("H"&B11*10&"!"&"C30") -> #REF! | AG11: =INDIRECT("H"&B11*10&"!"&"C32") -> #REF! | AH11: =INDIRECT("H"&B11*10&"!"&"C33") -> #REF! | AI11: =INDIRECT("H"&B11*10&"!"&"C34") -> #REF! | AJ11: =INDIRECT("H"&B11*10&"!"&"C31") -> #REF! | AL11: =INDIRECT("H"&B11*10&"!"&"T207") -> #REF! | AM11: =INDIRECT("H"&B11*10&"!"&"U207") -> #REF! | AN11: =INDIRECT("H"&B11*10&"!"&"AC207") -> #REF! | AO11: =INDIRECT("H"&B11*10&"!"&"AF207") -> #REF! | AQ11: =INDIRECT("H"&B11*10&"!"&"s195") -> #REF! | AR11: =INDIRECT("H"&B11*10&"!"&"T195") -> #REF! | AS11: =INDIRECT("H"&B11*10&"!"&"U195") -> #REF! | AT11: =AS11*(AQ11+AR11)/2 -> #REF! | AU11: =IF(INDIRECT("H"&B11*10&"!"&"L194")=" No requiere dentellon!!",0,1) -> #REF! | AX11: =AF13*(AG13+AH13+AI13)*1 -> #REF! | AY11: =AJ13*B13*1 -> #REF!
B12: =B11+0.5 -> 4.5 | C12: 0.375 | D12: 0.25 | E12: 0.625 | F12: 3 | G12: 0.5 | H12: 0.225 | I12: 0.5 | J12: 0.2 | K12: 0 | L12: 0 | M12: 0.5 | N12: 0.2 | O12: 0.5 | P12: 0.225 | Q12: 0.375 | R12: 0.225 | S12: 0.375 | T12: 0.15 | U12: 0.5 | V12: 0.2 | W12: 0.5 | X12: 0.2 | Z12: =CEILING(12*2.54*E12,5)/100 -> 0.2 | AA12: =CEILING(12*2.54*C12,5)/100 -> 0.15 | AB12: =IF((4*(C12*2.54)/100)<0.065,0.065,(4*(C12*2.54)/100)) -> 0.065 | AC12: =IF(K12=0,0,(VLOOKUP(K12,$AG$54:$AM$59,7,0)+AG12)) -> 0 | AD12: =CEILING(12*2.54*G12,5)/100 -> 0.2 | AF12: =INDIRECT("H"&B12*10&"!"&"C30") -> #REF! | AG12: =INDIRECT("H"&B12*10&"!"&"C32") -> #REF! | AH12: =INDIRECT("H"&B12*10&"!"&"C33") -> #REF! | AI12: =INDIRECT("H"&B12*10&"!"&"C34") -> #REF! | AJ12: =INDIRECT("H"&B12*10&"!"&"C31") -> #REF! | AL12: =INDIRECT("H"&B12*10&"!"&"T207") -> #REF! | AM12: =INDIRECT("H"&B12*10&"!"&"U207") -> #REF! | AN12: =INDIRECT("H"&B12*10&"!"&"AC207") -> #REF! | AO12: =INDIRECT("H"&B12*10&"!"&"AF207") -> #REF! | AQ12: =INDIRECT("H"&B12*10&"!"&"s195") -> #REF! | AR12: =INDIRECT("H"&B12*10&"!"&"T195") -> #REF! | AS12: =INDIRECT("H"&B12*10&"!"&"U195") -> #REF! | AT12: =AS12*(AQ12+AR12)/2 -> #REF! | AU12: =IF(INDIRECT("H"&B12*10&"!"&"L194")=" No requiere dentellon!!",0,1) -> #REF! | AX12: =AF14*(AG14+AH14+AI14)*1 -> 0 | AY12: =AJ14*B14*1 -> 30.25
B13: =B12+0.5 -> 5 | C13: 0.375 | D13: 0.25 | E13: 0.625 | F13: 4 | G13: 0.625 | H13: 0.25 | I13: 0.5 | J13: 0.2 | K13: 0 | L13: 0 | M13: 0.5 | N13: 0.2 | O13: 0.625 | P13: 0.25 | Q13: 0.375 | R13: 0.225 | S13: 0.375 | T13: 0.15 | U13: 0.5 | V13: 0.2 | W13: 0.5 | X13: 0.2 | Z13: =CEILING(12*2.54*E13,5)/100 -> 0.2 | AA13: =CEILING(12*2.54*C13,5)/100 -> 0.15 | AB13: =IF((4*(C13*2.54)/100)<0.065,0.065,(4*(C13*2.54)/100)) -> 0.065 | AC13: =IF(K13=0,0,(VLOOKUP(K13,$AG$54:$AM$59,7,0)+AG13)) -> 0 | AD13: =CEILING(12*2.54*G13,5)/100 -> 0.2 | AF13: =INDIRECT("H"&B13*10&"!"&"C30") -> #REF! | AG13: =INDIRECT("H"&B13*10&"!"&"C32") -> #REF! | AH13: =INDIRECT("H"&B13*10&"!"&"C33") -> #REF! | AI13: =INDIRECT("H"&B13*10&"!"&"C34") -> #REF! | AJ13: =INDIRECT("H"&B13*10&"!"&"C31") -> #REF! | AL13: =INDIRECT("H"&B13*10&"!"&"T207") -> #REF! | AM13: =INDIRECT("H"&B13*10&"!"&"U207") -> #REF! | AN13: =INDIRECT("H"&B13*10&"!"&"AC207") -> #REF! | AO13: =INDIRECT("H"&B13*10&"!"&"AF207") -> #REF! | AQ13: =INDIRECT("H"&B13*10&"!"&"s195") -> #REF! | AR13: =INDIRECT("H"&B13*10&"!"&"T195") -> #REF! | AS13: =INDIRECT("H"&B13*10&"!"&"U195") -> #REF! | AT13: =AS13*(AQ13+AR13)/2 -> #REF! | AU13: =IF(INDIRECT("H"&B13*10&"!"&"L194")=" No requiere dentellon!!",0,1) -> #REF! | AX13: =AF15*(AG15+AH15+AI15)*1 -> #REF! | AY13: =AJ15*B15*1 -> #REF!
B14: =B13+0.5 -> 5.5 | C14: 0.375 | D14: 0.25 | E14: 0.625 | F14: 4 | G14: 0.625 | H14: 0.25 | I14: 0.625 | J14: 0.25 | K14: 0 | L14: 0 | M14: 0.625 | N14: 0.25 | O14: 0.625 | P14: 0.25 | Q14: 0.375 | R14: 0.2 | S14: 0.375 | T14: 0.175 | U14: 0.625 | V14: 0.25 | W14: 0.625 | X14: 0.25 | Z14: =CEILING(12*2.54*E14,5)/100 -> 0.2 | AA14: =CEILING(12*2.54*C14,5)/100 -> 0.15 | AB14: =IF((4*(C14*2.54)/100)<0.065,0.065,(4*(C14*2.54)/100)) -> 0.065 | AC14: =IF(K14=0,0,(VLOOKUP(K14,$AG$54:$AM$59,7,0)+AG14)) -> 0 | AD14: =CEILING(12*2.54*G14,5)/100 -> 0.2 | AF14: =INDIRECT("H"&B14*10&"!"&"C30") -> 0 | AG14: =INDIRECT("H"&B14*10&"!"&"C32") -> 0.65 | AH14: =INDIRECT("H"&B14*10&"!"&"C33") -> 0 | AI14: =INDIRECT("H"&B14*10&"!"&"C34") -> 1 | AJ14: =INDIRECT("H"&B14*10&"!"&"C31") -> 5.5 | AL14: =INDIRECT("H"&B14*10&"!"&"T207") -> 0 | AM14: =INDIRECT("H"&B14*10&"!"&"U207") -> 0 | AN14: =INDIRECT("H"&B14*10&"!"&"AC207") -> 0 | AO14: =INDIRECT("H"&B14*10&"!"&"AF207") -> 0 | AQ14: =INDIRECT("H"&B14*10&"!"&"s195") -> 0 | AR14: =INDIRECT("H"&B14*10&"!"&"T195") -> 0 | AS14: =INDIRECT("H"&B14*10&"!"&"U195") -> 0 | AT14: =AS14*(AQ14+AR14)/2 -> 0 | AU14: =IF(INDIRECT("H"&B14*10&"!"&"L194")=" No requiere dentellon!!",0,1) -> 1 | AX14: =AF16*(AG16+AH16+AI16)*1 -> #REF! | AY14: =AJ16*B16*1 -> #REF!
B15: =B14+0.5 -> 6 | C15: 0.375 | D15: 0.25 | E15: 0.75 | F15: 4 | G15: 0.625 | H15: 0.25 | I15: 0.625 | J15: 0.25 | K15: 0 | L15: 0 | M15: 0.625 | N15: 0.25 | O15: 0.625 | P15: 0.25 | Q15: 0.375 | R15: 0.175 | S15: 0.375 | T15: =+R15 -> 0.175 | U15: 0.625 | V15: 0.25 | W15: 0.625 | X15: 0.25 | Z15: =CEILING(12*2.54*E15,5)/100 -> 0.25 | AA15: =CEILING(12*2.54*C15,5)/100 -> 0.15 | AB15: =IF((4*(C15*2.54)/100)<0.065,0.065,(4*(C15*2.54)/100)) -> 0.065 | AC15: =IF(K15=0,0,(VLOOKUP(K15,$AG$54:$AM$59,7,0)+AG15)) -> 0 | AD15: =CEILING(12*2.54*G15,5)/100 -> 0.2 | AF15: =INDIRECT("H"&B15*10&"!"&"C30") -> #REF! | AG15: =INDIRECT("H"&B15*10&"!"&"C32") -> #REF! | AH15: =INDIRECT("H"&B15*10&"!"&"C33") -> #REF! | AI15: =INDIRECT("H"&B15*10&"!"&"C34") -> #REF! | AJ15: =INDIRECT("H"&B15*10&"!"&"C31") -> #REF! | AL15: =INDIRECT("H"&B15*10&"!"&"T207") -> #REF! | AM15: =INDIRECT("H"&B15*10&"!"&"U207") -> #REF! | AN15: =INDIRECT("H"&B15*10&"!"&"AC207") -> #REF! | AO15: =INDIRECT("H"&B15*10&"!"&"AF207") -> #REF! | AQ15: =INDIRECT("H"&B15*10&"!"&"s195") -> #REF! | AR15: =INDIRECT("H"&B15*10&"!"&"T195") -> #REF! | AS15: =INDIRECT("H"&B15*10&"!"&"U195") -> #REF! | AT15: =AS15*(AQ15+AR15)/2 -> #REF! | AU15: =IF(INDIRECT("H"&B15*10&"!"&"L194")=" No requiere dentellon!!",0,1) -> #REF! | AX15: =AF17*(AG17+AH17+AI17)*1 -> #REF! | AY15: =AJ17*B17*1 -> #REF!
B16: =B15+0.5 -> 6.5 | C16: 0.375 | D16: 0.25 | E16: 0.75 | F16: 4 | G16: 0.625 | H16: 0.25 | I16: 0.625 | J16: 0.25 | K16: 0.5 | L16: 0.25 | M16: 0.625 | N16: 0.25 | O16: 0.625 | P16: 0.25 | Q16: 0.375 | R16: 0.175 | S16: 0.375 | T16: 0.175 | U16: 0.625 | V16: 0.25 | W16: 0.625 | X16: 0.25 | Z16: =CEILING(12*2.54*E16,5)/100 -> 0.25 | AA16: =CEILING(12*2.54*C16,5)/100 -> 0.15 | AB16: =IF((4*(C16*2.54)/100)<0.065,0.065,(4*(C16*2.54)/100)) -> 0.065 | AC16: =IF(K16=0,0,(VLOOKUP(K16,$AG$54:$AM$59,7,0)+AG16)) -> #REF! | AD16: =CEILING(12*2.54*G16,5)/100 -> 0.2 | AF16: =INDIRECT("H"&B16*10&"!"&"C30") -> #REF! | AG16: =INDIRECT("H"&B16*10&"!"&"C32") -> #REF! | AH16: =INDIRECT("H"&B16*10&"!"&"C33") -> #REF! | AI16: =INDIRECT("H"&B16*10&"!"&"C34") -> #REF! | AJ16: =INDIRECT("H"&B16*10&"!"&"C31") -> #REF! | AL16: =INDIRECT("H"&B16*10&"!"&"T207") -> #REF! | AM16: =INDIRECT("H"&B16*10&"!"&"U207") -> #REF! | AN16: =INDIRECT("H"&B16*10&"!"&"AC207") -> #REF! | AO16: =INDIRECT("H"&B16*10&"!"&"AF207") -> #REF! | AQ16: =INDIRECT("H"&B16*10&"!"&"s195") -> #REF! | AR16: =INDIRECT("H"&B16*10&"!"&"T195") -> #REF! | AS16: =INDIRECT("H"&B16*10&"!"&"U195") -> #REF! | AT16: =AS16*(AQ16+AR16)/2 -> #REF! | AU16: =IF(INDIRECT("H"&B16*10&"!"&"L194")=" No requiere dentellon!!",0,1) -> #REF! | AX16: =AF18*(AG18+AH18+AI18)*1 -> #REF! | AY16: =AJ18*B18*1 -> #REF!
B17: =B16+0.5 -> 7 | C17: 0.375 | D17: 0.25 | E17: 0.75 | F17: 5 | G17: 0.625 | H17: 0.25 | I17: 0.625 | J17: 0.25 | K17: 0.625 | L17: 0.25 | M17: 0.625 | N17: 0.25 | O17: 0.625 | P17: 0.25 | Q17: 0.375 | R17: 0.175 | S17: 0.375 | T17: 0.2 | U17: 0.625 | V17: 0.25 | W17: 0.625 | X17: 0.25 | Z17: =CEILING(12*2.54*E17,5)/100 -> 0.25 | AA17: =CEILING(12*2.54*C17,5)/100 -> 0.15 | AB17: =IF((4*(C17*2.54)/100)<0.065,0.065,(4*(C17*2.54)/100)) -> 0.065 | AC17: =IF(K17=0,0,(VLOOKUP(K17,$AG$54:$AM$59,7,0)+AG17)) -> #REF! | AD17: =CEILING(12*2.54*G17,5)/100 -> 0.2 | AF17: =INDIRECT("H"&B17*10&"!"&"C30") -> #REF! | AG17: =INDIRECT("H"&B17*10&"!"&"C32") -> #REF! | AH17: =INDIRECT("H"&B17*10&"!"&"C33") -> #REF! | AI17: =INDIRECT("H"&B17*10&"!"&"C34") -> #REF! | AJ17: =INDIRECT("H"&B17*10&"!"&"C31") -> #REF! | AL17: =INDIRECT("H"&B17*10&"!"&"T207") -> #REF! | AM17: =INDIRECT("H"&B17*10&"!"&"U207") -> #REF! | AN17: =INDIRECT("H"&B17*10&"!"&"AC207") -> #REF! | AO17: =INDIRECT("H"&B17*10&"!"&"AF207") -> #REF! | AQ17: =INDIRECT("H"&B17*10&"!"&"s195") -> #REF! | AR17: =INDIRECT("H"&B17*10&"!"&"T195") -> #REF! | AS17: =INDIRECT("H"&B17*10&"!"&"U195") -> #REF! | AT17: =AS17*(AQ17+AR17)/2 -> #REF! | AU17: =IF(INDIRECT("H"&B17*10&"!"&"L194")=" No requiere dentellon!!",0,1) -> #REF! | AX17: =AF19*(AG19+AH19+AI19)*1 -> #REF! | AY17: =AJ19*B19*1 -> #REF!
B18: =B17+0.5 -> 7.5 | C18: 0.375 | D18: =INDIRECT("H"&B18*10&"!"&"F313") -> #REF! | E18: 0.75 | F18: 5 | G18: 0.625 | H18: 0.25 | I18: 0.625 | J18: 0.25 | K18: 0.625 | L18: 0.25 | M18: 0.625 | N18: 0.25 | O18: 0.625 | P18: 0.25 | Q18: 0.5 | R18: 0.25 | S18: 0.375 | T18: 0.2 | U18: 0.625 | V18: 0.25 | W18: 0.625 | X18: 0.25 | Z18: =CEILING(12*2.54*E18,5)/100 -> 0.25 | AA18: =CEILING(12*2.54*C18,5)/100 -> 0.15 | AB18: =IF((4*(C18*2.54)/100)<0.065,0.065,(4*(C18*2.54)/100)) -> 0.065 | AC18: =IF(K18=0,0,(VLOOKUP(K18,$AG$54:$AM$59,7,0)+AG18)) -> #REF! | AD18: =CEILING(12*2.54*G18,5)/100 -> 0.2 | AF18: =INDIRECT("H"&B18*10&"!"&"C30") -> #REF! | AG18: =INDIRECT("H"&B18*10&"!"&"C32") -> #REF! | AH18: =INDIRECT("H"&B18*10&"!"&"C33") -> #REF! | AI18: =INDIRECT("H"&B18*10&"!"&"C34") -> #REF! | AJ18: =INDIRECT("H"&B18*10&"!"&"C31") -> #REF! | AL18: =INDIRECT("H"&B18*10&"!"&"T207") -> #REF! | AM18: =INDIRECT("H"&B18*10&"!"&"U207") -> #REF! | AN18: =INDIRECT("H"&B18*10&"!"&"AC207") -> #REF! | AO18: =INDIRECT("H"&B18*10&"!"&"AF207") -> #REF! | AQ18: =INDIRECT("H"&B18*10&"!"&"s195") -> #REF! | AR18: =INDIRECT("H"&B18*10&"!"&"T195") -> #REF! | AS18: =INDIRECT("H"&B18*10&"!"&"U195") -> #REF! | AT18: =AS18*(AQ18+AR18)/2 -> #REF! | AU18: =IF(INDIRECT("H"&B18*10&"!"&"L194")=" No requiere dentellon!!",0,1) -> #REF! | AX18: =AF20*(AG20+AH20+AI20)*1 -> #REF! | AY18: =AJ20*B20*1 -> #REF!
B19: =B18+0.5 -> 8 | C19: 0.375 | D19: 0.2 | E19: 0.75 | F19: 5 | G19: 0.625 | H19: 0.2 | I19: 0.625 | J19: 0.225 | K19: 0.625 | L19: 0.225 | M19: 0.625 | N19: 0.225 | O19: 0.625 | P19: 0.2 | Q19: 0.5 | R19: 0.25 | S19: 0.375 | T19: 0.2 | U19: 0.625 | V19: 0.225 | W19: 0.625 | X19: 0.225 | Z19: =CEILING(12*2.54*E19,5)/100 -> 0.25 | AA19: =CEILING(12*2.54*C19,5)/100 -> 0.15 | AB19: =IF((4*(C19*2.54)/100)<0.065,0.065,(4*(C19*2.54)/100)) -> 0.065 | AC19: =IF(K19=0,0,(VLOOKUP(K19,$AG$54:$AM$59,7,0)+AG19)) -> #REF! | AD19: =CEILING(12*2.54*G19,5)/100 -> 0.2 | AF19: =INDIRECT("H"&B19*10&"!"&"C30") -> #REF! | AG19: =INDIRECT("H"&B19*10&"!"&"C32") -> #REF! | AH19: =INDIRECT("H"&B19*10&"!"&"C33") -> #REF! | AI19: =INDIRECT("H"&B19*10&"!"&"C34") -> #REF! | AJ19: =INDIRECT("H"&B19*10&"!"&"C31") -> #REF! | AL19: =INDIRECT("H"&B19*10&"!"&"T207") -> #REF! | AM19: =INDIRECT("H"&B19*10&"!"&"U207") -> #REF! | AN19: =INDIRECT("H"&B19*10&"!"&"AC207") -> #REF! | AO19: =INDIRECT("H"&B19*10&"!"&"AF207") -> #REF! | AQ19: =INDIRECT("H"&B19*10&"!"&"s195") -> #REF! | AR19: =INDIRECT("H"&B19*10&"!"&"T195") -> #REF! | AS19: =INDIRECT("H"&B19*10&"!"&"U195") -> #REF! | AT19: =AS19*(AQ19+AR19)/2 -> #REF! | AU19: =IF(INDIRECT("H"&B19*10&"!"&"L194")=" No requiere dentellon!!",0,1) -> #REF! | AX19: =AF21*(AG21+AH21+AI21)*1 -> #REF! | AY19: =AJ21*B21*1 -> #REF!
B20: =B19+0.5 -> 8.5 | C20: 0.375 | D20: 0.175 | E20: =INDIRECT("H"&B20*10&"!"&"E312") -> #REF! | F20: 4 | G20: 0.75 | H20: 0.25 | I20: 0.625 | J20: 0.2 | K20: 0.625 | L20: 0.3 | M20: 0.625 | N20: 0.2 | O20: 0.75 | P20: 0.25 | Q20: 0.5 | R20: 0.225 | S20: 0.375 | T20: 0.2 | U20: 0.625 | V20: 0.2 | W20: 0.625 | X20: 0.2 | Z20: =CEILING(12*2.54*E20,5)/100 -> #REF! | AA20: =CEILING(12*2.54*C20,5)/100 -> 0.15 | AB20: =IF((4*(C20*2.54)/100)<0.065,0.065,(4*(C20*2.54)/100)) -> 0.065 | AC20: =IF(K20=0,0,(VLOOKUP(K20,$AG$54:$AM$59,7,0)+AG20)) -> #REF! | AD20: =CEILING(12*2.54*G20,5)/100 -> 0.25 | AF20: =INDIRECT("H"&B20*10&"!"&"C30") -> #REF! | AG20: =INDIRECT("H"&B20*10&"!"&"C32") -> #REF! | AH20: =INDIRECT("H"&B20*10&"!"&"C33") -> #REF! | AI20: =INDIRECT("H"&B20*10&"!"&"C34") -> #REF! | AJ20: =INDIRECT("H"&B20*10&"!"&"C31") -> #REF! | AL20: =INDIRECT("H"&B20*10&"!"&"T207") -> #REF! | AM20: =INDIRECT("H"&B20*10&"!"&"U207") -> #REF! | AN20: =INDIRECT("H"&B20*10&"!"&"AC207") -> #REF! | AO20: =INDIRECT("H"&B20*10&"!"&"AF207") -> #REF! | AQ20: =INDIRECT("H"&B20*10&"!"&"s195") -> #REF! | AR20: =INDIRECT("H"&B20*10&"!"&"T195") -> #REF! | AS20: =INDIRECT("H"&B20*10&"!"&"U195") -> #REF! | AT20: =AS20*(AQ20+AR20)/2 -> #REF! | AU20: =IF(INDIRECT("H"&B20*10&"!"&"L194")=" No requiere dentellon!!",0,1) -> #REF!
B21: =B20+0.5 -> 9 | C21: 0.375 | D21: 0.15 | E21: 1 | F21: 4 | G21: 0.75 | H21: 0.25 | I21: 0.625 | J21: 0.2 | K21: 0.75 | L21: 0.25 | M21: 0.625 | N21: 0.2 | O21: 0.75 | P21: 0.25 | Q21: 0.5 | R21: 0.225 | S21: 0.375 | T21: 0.2 | U21: 0.625 | V21: 0.2 | W21: 0.625 | X21: 0.2 | Z21: =CEILING(12*2.54*E21,5)/100 -> 0.35 | AA21: =CEILING(12*2.54*C21,5)/100 -> 0.15 | AB21: =IF((4*(C21*2.54)/100)<0.065,0.065,(4*(C21*2.54)/100)) -> 0.065 | AC21: =IF(K21=0,0,(VLOOKUP(K21,$AG$54:$AM$59,7,0)+AG21)) -> #REF! | AD21: =CEILING(12*2.54*G21,5)/100 -> 0.25 | AF21: =INDIRECT("H"&B21*10&"!"&"C30") -> #REF! | AG21: =INDIRECT("H"&B21*10&"!"&"C32") -> #REF! | AH21: =INDIRECT("H"&B21*10&"!"&"C33") -> #REF! | AI21: =INDIRECT("H"&B21*10&"!"&"C34") -> #REF! | AJ21: =INDIRECT("H"&B21*10&"!"&"C31") -> #REF! | AL21: =INDIRECT("H"&B21*10&"!"&"T207") -> #REF! | AM21: =INDIRECT("H"&B21*10&"!"&"U207") -> #REF! | AN21: =INDIRECT("H"&B21*10&"!"&"AC207") -> #REF! | AO21: =INDIRECT("H"&B21*10&"!"&"AF207") -> #REF! | AQ21: =INDIRECT("H"&B21*10&"!"&"s195") -> #REF! | AR21: =INDIRECT("H"&B21*10&"!"&"T195") -> #REF! | AS21: =INDIRECT("H"&B21*10&"!"&"U195") -> #REF! | AT21: =AS21*(AQ21+AR21)/2 -> #REF! | AU21: =IF(INDIRECT("H"&B21*10&"!"&"L194")=" No requiere dentellon!!",0,1) -> #REF!
B22: =B21+0.5 -> 9.5 | C22: =INDIRECT("H"&B22*10&"!"&"E313") -> #REF! | D22: =INDIRECT("H"&B22*10&"!"&"F313") -> #REF! | E22: =INDIRECT("H"&B22*10&"!"&"E312") -> #REF! | F22: =INDIRECT("H"&B22*10&"!"&"F312") -> #REF! | G22: =INDIRECT("H"&B22*10&"!"&"E341") -> #REF! | H22: =INDIRECT("H"&B22*10&"!"&"H341") -> #REF! | I22: =INDIRECT("H"&B22*10&"!"&"E373") -> #REF! | J22: =INDIRECT("H"&B22*10&"!"&"F373") -> #REF! | K22: =INDIRECT("H"&B22*10&"!"&"E372") -> #REF! | L22: =INDIRECT("H"&B22*10&"!"&"F372") -> #REF! | M22: =INDIRECT("H"&B22*10&"!"&"E439") -> #REF! | N22: =INDIRECT("H"&B22*10&"!"&"F439") -> #REF! | O22: =INDIRECT("H"&B22*10&"!"&"E438") -> #REF! | P22: =INDIRECT("H"&B22*10&"!"&"F438") -> #REF! | Q22: =+G22 -> #REF! | R22: =+H22 -> #REF! | S22: =+Q22 -> #REF! | T22: =+R22 -> #REF! | U22: =INDIRECT("H"&B22*10&"!"&"E465") -> #REF! | V22: =INDIRECT("H"&B22*10&"!"&"h465") -> #REF! | W22: =+U22 -> #REF! | X22: =+V22 -> #REF! | Z22: =IF(INDIRECT("H"&B22*10&"!"&"G312")=0,0,INDIRECT("H"&B22*10&"!"&"G312")+VLOOKUP(E22,$AG$54:$AM$59,7,0)) -> #REF! | AA22: =CEILING(12*2.54*C22,5)/100 -> #REF! | AB22: =+AF22-(0.075+(C22*2.54/2)/100) -> #REF! | AC22: =IF(INDIRECT("H"&B22*10&"!"&"G372")=0,0,INDIRECT("H"&B22*10&"!"&"G372")+2*VLOOKUP(K22,$AG$54:$AM$59,7,0)) -> #REF! | AD22: =IF(INDIRECT("H"&B22*10&"!"&"G438")=0,0,INDIRECT("H"&B22*10&"!"&"G438")+2*VLOOKUP(O22,$AG$54:$AM$59,7,0)) -> #REF! | AF22: =INDIRECT("H"&B22*10&"!"&"C30") -> #REF! | AG22: =INDIRECT("H"&B22*10&"!"&"C32") -> #REF! | AH22: =INDIRECT("H"&B22*10&"!"&"C33") -> #REF! | AI22: =INDIRECT("H"&B22*10&"!"&"C34") -> #REF! | AJ22: =INDIRECT("H"&B22*10&"!"&"C31") -> #REF! | AL22: =INDIRECT("H"&B22*10&"!"&"T207") -> #REF! | AM22: =INDIRECT("H"&B22*10&"!"&"U207") -> #REF! | AN22: =INDIRECT("H"&B22*10&"!"&"AC207") -> #REF! | AO22: =INDIRECT("H"&B22*10&"!"&"AF207") -> #REF! | AQ22: =INDIRECT("H"&B22*10&"!"&"s195") -> #REF! | AR22: =INDIRECT("H"&B22*10&"!"&"T195") -> #REF! | AS22: =INDIRECT("H"&B22*10&"!"&"U195") -> #REF! | AT22: =AS22*(AQ22+AR22)/2 -> #REF! | AU22: =IF(INDIRECT("H"&B22*10&"!"&"L194")=" No requiere dentellon!!",0,1) -> #REF!
B23: =B22+0.5 -> 10 | C23: =INDIRECT("H"&B23*10&"!"&"E313") -> #REF! | D23: =INDIRECT("H"&B23*10&"!"&"F313") -> #REF! | E23: =INDIRECT("H"&B23*10&"!"&"E312") -> #REF! | F23: =INDIRECT("H"&B23*10&"!"&"F312") -> #REF! | G23: =INDIRECT("H"&B23*10&"!"&"E341") -> #REF! | H23: =INDIRECT("H"&B23*10&"!"&"H341") -> #REF! | I23: =INDIRECT("H"&B23*10&"!"&"E373") -> #REF! | J23: =INDIRECT("H"&B23*10&"!"&"F373") -> #REF! | K23: =INDIRECT("H"&B23*10&"!"&"E372") -> #REF! | L23: =INDIRECT("H"&B23*10&"!"&"F372") -> #REF! | M23: =INDIRECT("H"&B23*10&"!"&"E439") -> #REF! | N23: =INDIRECT("H"&B23*10&"!"&"F439") -> #REF! | O23: =INDIRECT("H"&B23*10&"!"&"E438") -> #REF! | P23: =INDIRECT("H"&B23*10&"!"&"F438") -> #REF! | Q23: =+G23 -> #REF! | R23: =+H23 -> #REF! | S23: =+Q23 -> #REF! | T23: =+R23 -> #REF! | U23: =INDIRECT("H"&B23*10&"!"&"E465") -> #REF! | V23: =INDIRECT("H"&B23*10&"!"&"h465") -> #REF! | W23: =+U23 -> #REF! | X23: =+V23 -> #REF! | Z23: =IF(INDIRECT("H"&B23*10&"!"&"G312")=0,0,INDIRECT("H"&B23*10&"!"&"G312")+VLOOKUP(E23,$AG$54:$AM$59,7,0)) -> #REF! | AA23: =CEILING(12*2.54*C23,5)/100 -> #REF! | AB23: =+AF23-(0.075+(C23*2.54/2)/100) -> #REF! | AC23: =IF(INDIRECT("H"&B23*10&"!"&"G372")=0,0,INDIRECT("H"&B23*10&"!"&"G372")+2*VLOOKUP(K23,$AG$54:$AM$59,7,0)) -> #REF! | AD23: =IF(INDIRECT("H"&B23*10&"!"&"G438")=0,0,INDIRECT("H"&B23*10&"!"&"G438")+2*VLOOKUP(O23,$AG$54:$AM$59,7,0)) -> #REF! | AF23: =INDIRECT("H"&B23*10&"!"&"C30") -> #REF! | AG23: =INDIRECT("H"&B23*10&"!"&"C32") -> #REF! | AH23: =INDIRECT("H"&B23*10&"!"&"C33") -> #REF! | AI23: =INDIRECT("H"&B23*10&"!"&"C34") -> #REF! | AJ23: =INDIRECT("H"&B23*10&"!"&"C31") -> #REF! | AL23: =INDIRECT("H"&B23*10&"!"&"T207") -> #REF! | AM23: =INDIRECT("H"&B23*10&"!"&"U207") -> #REF! | AN23: =INDIRECT("H"&B23*10&"!"&"AC207") -> #REF! | AO23: =INDIRECT("H"&B23*10&"!"&"AF207") -> #REF! | AQ23: =INDIRECT("H"&B23*10&"!"&"s195") -> #REF! | AR23: =INDIRECT("H"&B23*10&"!"&"T195") -> #REF! | AS23: =INDIRECT("H"&B23*10&"!"&"U195") -> #REF! | AT23: =AS23*(AQ23+AR23)/2 -> #REF! | AU23: =IF(INDIRECT("H"&B23*10&"!"&"L194")=" No requiere dentellon!!",0,1) -> #REF!
B24: =B23+0.5 -> 10.5 | C24: =INDIRECT("H"&B24*10&"!"&"E313") -> #REF! | D24: =INDIRECT("H"&B24*10&"!"&"F313") -> #REF! | E24: =INDIRECT("H"&B24*10&"!"&"E312") -> #REF! | F24: =INDIRECT("H"&B24*10&"!"&"F312") -> #REF! | G24: =INDIRECT("H"&B24*10&"!"&"E341") -> #REF! | H24: =INDIRECT("H"&B24*10&"!"&"H341") -> #REF! | I24: =INDIRECT("H"&B24*10&"!"&"E373") -> #REF! | J24: =INDIRECT("H"&B24*10&"!"&"F373") -> #REF! | K24: =INDIRECT("H"&B24*10&"!"&"E372") -> #REF! | L24: =INDIRECT("H"&B24*10&"!"&"F372") -> #REF! | M24: =INDIRECT("H"&B24*10&"!"&"E439") -> #REF! | N24: =INDIRECT("H"&B24*10&"!"&"F439") -> #REF! | O24: =INDIRECT("H"&B24*10&"!"&"E438") -> #REF! | P24: =INDIRECT("H"&B24*10&"!"&"F438") -> #REF! | Q24: =+G24 -> #REF! | R24: =+H24 -> #REF! | S24: =+Q24 -> #REF! | T24: =+R24 -> #REF! | U24: =INDIRECT("H"&B24*10&"!"&"E465") -> #REF! | V24: =INDIRECT("H"&B24*10&"!"&"h465") -> #REF! | W24: =+U24 -> #REF! | X24: =+V24 -> #REF! | Z24: =IF(INDIRECT("H"&B24*10&"!"&"G312")=0,0,INDIRECT("H"&B24*10&"!"&"G312")+VLOOKUP(E24,$AG$54:$AM$59,7,0)) -> #REF! | AA24: =CEILING(12*2.54*C24,5)/100 -> #REF! | AB24: =+AF24-(0.075+(C24*2.54/2)/100) -> #REF! | AC24: =IF(INDIRECT("H"&B24*10&"!"&"G372")=0,0,INDIRECT("H"&B24*10&"!"&"G372")+2*VLOOKUP(K24,$AG$54:$AM$59,7,0)) -> #REF! | AD24: =IF(INDIRECT("H"&B24*10&"!"&"G438")=0,0,INDIRECT("H"&B24*10&"!"&"G438")+2*VLOOKUP(O24,$AG$54:$AM$59,7,0)) -> #REF! | AF24: =INDIRECT("H"&B24*10&"!"&"C30") -> #REF! | AG24: =INDIRECT("H"&B24*10&"!"&"C32") -> #REF! | AH24: =INDIRECT("H"&B24*10&"!"&"C33") -> #REF! | AI24: =INDIRECT("H"&B24*10&"!"&"C34") -> #REF! | AJ24: =INDIRECT("H"&B24*10&"!"&"C31") -> #REF! | AL24: =INDIRECT("H"&B24*10&"!"&"T207") -> #REF! | AM24: =INDIRECT("H"&B24*10&"!"&"U207") -> #REF! | AN24: =INDIRECT("H"&B24*10&"!"&"AC207") -> #REF! | AO24: =INDIRECT("H"&B24*10&"!"&"AF207") -> #REF! | AQ24: =INDIRECT("H"&B24*10&"!"&"s195") -> #REF! | AR24: =INDIRECT("H"&B24*10&"!"&"T195") -> #REF! | AS24: =INDIRECT("H"&B24*10&"!"&"U195") -> #REF! | AT24: =AS24*(AQ24+AR24)/2 -> #REF! | AU24: =IF(INDIRECT("H"&B24*10&"!"&"L194")=" No requiere dentellon!!",0,1) -> #REF!
C26: 1.5 | D26: =C26+0.5 -> 2 | E26: =D26+0.5 -> 2.5 | F26: =E26+0.5 -> 3 | G26: =F26+0.5 -> 3.5 | H26: =G26+0.5 -> 4 | I26: =H26+0.5 -> 4.5 | J26: =I26+0.5 -> 5 | K26: =J26+0.5 -> 5.5 | ... U26: =T26+0.5 -> 10.5
B28: Longitud de acero por (m) | N28: UÑA
B29: H | C29: A1 | D29: A2 | E29: A3 | F29: A4 | G29: A5 | H29: A6 | I29: A7 | J29: A8 trans | K29: A9 trans | L29: A10 trans | M29: A11 trans | N29: A12 | O29: A13trans
B30: 1.5 | C30: =B6+(0.3-0.04)+0.1+AB6+AA6 -> #REF! | D30: =+IF(Z6=0,0,Z6+AB6+AA6) -> #REF! | E30: =0.1+AB6+SQRT((B6+0.3-0.04)^2+(AH6-AJ6-0.04)^2) -> #REF! | F30: =0.2+0.2+(AG6+AH6+AI6-2*0.075) -> #REF! | G30: =+AC6 -> #REF! | H30: =0.2+0.2+AG6+AH6+AI6-2*0.075 -> #REF! | I30: =+AD6 -> #REF! | J30: 1 | K30: 1 | L30: 1 | M30: 1 | N30: =2*(12*AL6*0.0254)+2*(AF6-0.075)+2*SQRT((AS6-0.075)^2+((AQ6-AR6)/2-0.075)^2)+(AR6-2*0.075) -> #REF! | O30: 1
B31: =B30+0.5 -> 2 | C31: =B7+AB7+AF7+AA7+AJ7 -> #REF! | D31: =K98+L98+C98+AJ7+AF7/COS(RADIANS(J98))+Z7 -> #REF! | E31: =(E98+F98+AF7+AD7) -> #REF! | F31: =0.2+0.2+(AG7+AH7+AI7-2*0.075) -> #REF! | G31: =+AC7 -> 0 | H31: =0.2+0.2+AG7+AH7+AI7-2*0.075 -> #REF! | I31: =E31 -> #REF! | J31: 1 | K31: =(M98+0.1+0.1)*2 -> 2.435 | L31: 1 | M31: 1 | N31: =2*(12*AL7*0.0254)+2*(AF7-0.075)+2*SQRT((AS7-0.075)^2+((AQ7-AR7)/2-0.075)^2)+(AR7-2*0.075) -> #REF! | O31: 1
B32: =B31+0.5 -> 2.5 | C32: =B8+AB8+AF8+AA8+AJ8 -> #REF! | D32: =K99+L99+C99+AJ8+AF8/COS(RADIANS(J99))+Z8 -> #REF! | E32: =(E99+F99+AF8+AD8) -> #REF! | F32: =0.2+0.2+(AG8+AH8+AI8-2*0.075) -> #REF! | G32: =+AC8 -> 0 | H32: =0.2+0.2+AG8+AH8+AI8-2*0.075 -> #REF! | I32: =E32 -> #REF! | J32: 1 | K32: =(M99+0.1+0.1)*2 -> 2.435 | L32: 1 | M32: 1 | N32: =2*(12*AL8*0.0254)+2*(AF8-0.075)+2*SQRT((AS8-0.075)^2+((AQ8-AR8)/2-0.075)^2)+(AR8-2*0.075) -> #REF! | O32: 1
B33: =B32+0.5 -> 3 | C33: =B9+AB9+AF9+AA9+AJ9 -> #REF! | D33: =K100+L100+C100+AJ9+AF9/COS(RADIANS(J100))+Z9 -> #REF! | E33: =(E100+F100+AF9+AD9) -> #REF! | F33: =0.2+0.2+(AG9+AH9+AI9-2*0.075) -> #REF! | G33: =+AC9 -> 0 | H33: =0.2+0.2+AG9+AH9+AI9-2*0.075 -> #REF! | I33: =E33 -> #REF! | J33: 1 | K33: =(M100+0.1+0.1)*2 -> 2.435 | L33: 1 | M33: 1 | N33: =2*(12*AL9*0.0254)+2*(AF9-0.075)+2*SQRT((AS9-0.075)^2+((AQ9-AR9)/2-0.075)^2)+(AR9-2*0.075) -> #REF! | O33: 1
B34: =B33+0.5 -> 3.5 | C34: =B10+AB10+AF10+AA10+AJ10 -> #REF! | D34: =K101+L101+C101+AJ10+AF10/COS(RADIANS(J101))+Z10 -> #REF! | E34: =(E101+F101+AF10+AD10) -> #REF! | F34: =0.2+0.2+(AG10+AH10+AI10-2*0.075) -> #REF! | G34: =+AC10 -> 0 | H34: =0.2+0.2+AG10+AH10+AI10-2*0.075 -> #REF! | I34: =E34 -> #REF! | J34: 1 | K34: =(M101+0.1+0.1)*2 -> 2.435 | L34: 1 | M34: 1 | N34: =2*(12*AL10*0.0254)+2*(AF10-0.075)+2*SQRT((AS10-0.075)^2+((AQ10-AR10)/2-0.075)^2)+(AR10-2*0.075) -> #REF! | O34: 1 | AH34: Longitud básica de anclaje ldh ACI 12.5.2
B35: =B34+0.5 -> 4 | C35: =B11+AB11+AF11+AA11+AJ11 -> #REF! | D35: =K102+L102+C102+AJ11+AF11/COS(RADIANS(J102))+Z11 -> #REF! | E35: =(E102+F102+AF11+AD11) -> #REF! | F35: =0.2+0.2+(AG11+AH11+AI11-2*0.075) -> #REF! | G35: =+AC11 -> 0 | H35: =0.2+0.2+AG11+AH11+AI11-2*0.075 -> #REF! | I35: =E35 -> #REF! | J35: 1 | K35: =(M102+0.1+0.1)*2 -> 2.435 | L35: 1 | M35: 1 | N35: =2*(12*AL11*0.0254)+2*(AF11-0.075)+2*SQRT((AS11-0.075)^2+((AQ11-AR11)/2-0.075)^2)+(AR11-2*0.075) -> #REF! | O35: 1 | AH35: fy | AI35: 4200
B36: =B35+0.5 -> 4.5 | C36: =B12+AB12+AF12+AA12+AJ12 -> #REF! | D36: =K103+L103+C103+AJ12+AF12/COS(RADIANS(J103))+Z12 -> #REF! | E36: =(E103+F103+AF12+AD12) -> #REF! | F36: =0.2+0.2+(AG12+AH12+AI12-2*0.075) -> #REF! | G36: =+AC12 -> 0 | H36: =0.2+0.2+AG12+AH12+AI12-2*0.075 -> #REF! | I36: =E36 -> #REF! | J36: 1 | K36: =(M103+0.1+0.1)*2 -> 2.435 | L36: 1 | M36: 1 | N36: =2*(12*AL12*0.0254)+2*(AF12-0.075)+2*SQRT((AS12-0.075)^2+((AQ12-AR12)/2-0.075)^2)+(AR12-2*0.075) -> #REF! | O36: 1 | AH36: f´c | AI36: 210
B37: =B36+0.5 -> 5 | C37: =B13+AB13+AF13+AA13+AJ13 -> #REF! | D37: =K104+L104+C104+AJ13+AF13/COS(RADIANS(J104))+Z13 -> #REF! | E37: =(E104+F104+AF13+AD13) -> #REF! | F37: =0.2+0.2+(AG13+AH13+AI13-2*0.075) -> #REF! | G37: =+AC13 -> 0 | H37: =0.2+0.2+AG13+AH13+AI13-2*0.075 -> #REF! | I37: =E37 -> #REF! | J37: 1 | K37: =(M104+0.1+0.1)*2 -> 2.435 | L37: 1 | M37: 1 | N37: =2*(12*AL13*0.0254)+2*(AF13-0.075)+2*SQRT((AS13-0.075)^2+((AQ13-AR13)/2-0.075)^2)+(AR13-2*0.075) -> #REF! | O37: 1 | AI37: ldh | AJ37: >= 8db | AK37: Min altura de zapata
B38: =B37+0.5 -> 5.5 | C38: =B14+AB14+AF14+AA14+AJ14 -> 11.215 | D38: =K105+L105+C105+AJ14+AF14/COS(RADIANS(J105))+Z14 -> 13.561751 | E38: =(E105+F105+AF14+AD14) -> 7.7 | F38: =0.2+0.2+(AG14+AH14+AI14-2*0.075) -> 1.9 | G38: =+AC14 -> 0 | H38: =0.2+0.2+AG14+AH14+AI14-2*0.075 -> 1.9 | I38: =E38 -> 7.7 | J38: 1 | K38: =(M105+0.1+0.1)*2 -> 2.435 | L38: 1 | M38: 1 | N38: =2*(12*AL14*0.0254)+2*(AF14-0.075)+2*SQRT((AS14-0.075)^2+((AQ14-AR14)/2-0.075)^2)+(AR14-2*0.075) -> -0.087867966 | O38: 1 | AH38: 1 | AI38: =0.0766*$AI$35*AH38*2.54/SQRT($AI$36) -> 56.390005 | AJ38: =8*AH38*2.54 -> 20.32 | AK38: =ROUNDUP(AI38+9,0) -> 66
B39: =B38+0.5 -> 6 | C39: =B15+AB15+AF15+AA15+AJ15 -> #REF! | D39: =K106+L106+C106+AJ15+AF15/COS(RADIANS(J106))+Z15 -> #REF! | E39: =(E106+F106+AF15+AD15) -> #REF! | F39: =0.2+0.2+(AG15+AH15+AI15-2*0.075) -> #REF! | G39: =+AC15 -> 0 | H39: =0.2+0.2+AG15+AH15+AI15-2*0.075 -> #REF! | I39: =E39 -> #REF! | J39: 1 | K39: =(M106+0.1+0.1)*2 -> 2.435 | L39: 1 | M39: 1 | N39: =2*(12*AL15*0.0254)+2*(AF15-0.075)+2*SQRT((AS15-0.075)^2+((AQ15-AR15)/2-0.075)^2)+(AR15-2*0.075) -> #REF! | O39: 1 | AH39: 0.75 | AI39: =0.0766*$AI$35*AH39*2.54/SQRT($AI$36) -> 42.292503 | AJ39: =8*AH39*2.54 -> 15.24 | AK39: =ROUNDUP(AI39+9,0) -> 52
B40: =B39+0.5 -> 6.5 | C40: =B16+AB16+AF16+AA16+AJ16 -> #REF! | D40: =K107+L107+C107+AJ16+AF16/COS(RADIANS(J107))+Z16 -> #REF! | E40: =(E107+F107+AF16+AD16) -> #REF! | F40: =0.2+0.2+(AG16+AH16+AI16-2*0.075) -> #REF! | G40: =+AC16 -> #REF! | H40: =0.2+0.2+AG16+AH16+AI16-2*0.075 -> #REF! | I40: =E40 -> #REF! | J40: 1 | K40: =(M107+0.1+0.1)*2 -> 2.435 | L40: 1 | M40: 1 | N40: =2*(12*AL16*0.0254)+2*(AF16-0.075)+2*SQRT((AS16-0.075)^2+((AQ16-AR16)/2-0.075)^2)+(AR16-2*0.075) -> #REF! | O40: 1 | AH40: 0.625 | AI40: =0.0766*$AI$35*AH40*2.54/SQRT($AI$36) -> 35.243753 | AJ40: =8*AH40*2.54 -> 12.7 | AK40: =ROUNDUP(AI40+9,0) -> 45
B41: =B40+0.5 -> 7 | C41: =B17+AB17+AF17+AA17+AJ17 -> #REF! | D41: =K108+L108+C108+AJ17+AF17/COS(RADIANS(J108))+Z17 -> #REF! | E41: =(E108+F108+AF17+AD17) -> #REF! | F41: =0.2+0.2+(AG17+AH17+AI17-2*0.075) -> #REF! | G41: =+AC17 -> #REF! | H41: =0.2+0.2+AG17+AH17+AI17-2*0.075 -> #REF! | I41: =E41 -> #REF! | J41: 1 | K41: =(M108+0.1+0.1)*2 -> 2.435 | L41: 1 | M41: 1 | N41: =2*(12*AL17*0.0254)+2*(AF17-0.075)+2*SQRT((AS17-0.075)^2+((AQ17-AR17)/2-0.075)^2)+(AR17-2*0.075) -> #REF! | O41: 1 | AH41: 0.5 | AI41: =0.0766*$AI$35*AH41*2.54/SQRT($AI$36) -> 28.195002 | AJ41: =8*AH41*2.54 -> 10.16 | AK41: =ROUNDUP(AI41+9,0) -> 38
B42: =B41+0.5 -> 7.5 | C42: =B18+AB18+AF18+AA18+AJ18 -> #REF! | D42: =K109+L109+C109+AJ18+AF18/COS(RADIANS(J109))+Z18 -> #REF! | E42: =(E109+F109+AF18+AD18) -> #REF! | F42: =0.2+0.2+(AG18+AH18+AI18-2*0.075) -> #REF! | G42: =+AC18 -> #REF! | H42: =0.2+0.2+AG18+AH18+AI18-2*0.075 -> #REF! | I42: =E42 -> #REF! | J42: 1 | K42: =(M109+0.1+0.1)*2 -> 2.435 | L42: 1 | M42: 1 | N42: =2*(12*AL18*0.0254)+2*(AF18-0.075)+2*SQRT((AS18-0.075)^2+((AQ18-AR18)/2-0.075)^2)+(AR18-2*0.075) -> #REF! | O42: 1 | AH42: 0.375 | AI42: =0.0766*$AI$35*AH42*2.54/SQRT($AI$36) -> 21.146252 | AJ42: =8*AH42*2.54 -> 7.62 | AK42: =ROUNDUP(AI42+9,0) -> 31
B43: =B42+0.5 -> 8 | C43: =B19+AB19+AF19+AA19+AJ19 -> #REF! | D43: =K110+L110+C110+AJ19+AF19/COS(RADIANS(J110))+Z19 -> #REF! | E43: =(E110+F110+AF19+AD19) -> #REF! | F43: =0.2+0.2+(AG19+AH19+AI19-2*0.075) -> #REF! | G43: =+AC19 -> #REF! | H43: =0.2+0.2+AG19+AH19+AI19-2*0.075 -> #REF! | I43: =E43 -> #REF! | J43: 1 | K43: =(M110+0.1+0.1)*2 -> 2.435 | L43: 1 | M43: 1 | N43: =2*(12*AL19*0.0254)+2*(AF19-0.075)+2*SQRT((AS19-0.075)^2+((AQ19-AR19)/2-0.075)^2)+(AR19-2*0.075) -> #REF! | O43: 1
...

Sheet ResMet
D3: PROYECTO: 181307: EXPEDIENTE TECNICO OBRAS DE CONTENCION
H5: 4 | I5: =+H5+3 -> 7 | J5: =+I5+3 -> 10 | K5: =+J5+3 -> 13 | L5: =+K5+3 -> 16 | M5: =+L5+6 -> 22 | N5: =+M5+3 -> 25 | O5: =+N5+3 -> 28 | P5: 31
C6: Progresiva | D6: Progresiva Inicial | E6: Progresiva Final | F6: Longitud | G6: Altura | H6: Corte de terreno | I6: Relleno con material seleccionado | J6: Solado f'c=100Kg/cm2 e=5cm | K6: Concreto f'c=210Kg/cm2 | L6: Encofrado Longitudinal | M6: Armadura | N6: Juntas de dilatacion | O6: Tubos de Drenaje Longitudinal Diametro 6" | P6: Geocompuesto de drenaje (ambas caras con geotextil permeable - no tejido) | R6: corte CAD | S6: relleno CAD
C7: Km | D7: Km | E7: Km | F7: m | G7: m | H7: m3 | I7: m3 | J7: m2 | K7: m3 | L7: m2 | M7: Kg | N7: m2 | O7: m | P7: m
C9: =+(D9+E9)/2 -> 393.145 | D9: 391.29 | E9: 395 | F9: =+E9-D9 -> 3.71 | G9: 2.5 | H9: =+R9*F9 -> 42.9989 | I9: =+S9*F9 -> 22.1858 | J9: =HLOOKUP($G9,#REF!,$J$5,1)*$F9 -> #REF! | K9: =HLOOKUP($G9,#REF!,$K$5,0)*$F9 -> #REF! | L9: =HLOOKUP($G9,#REF!,$L$5,0)*$F9 -> #REF! | M9: =HLOOKUP($G9,#REF!,$M$5,0)*$F9 -> #REF! | N9: =HLOOKUP($G9,#REF!,$N$5,0)*$F9 -> #REF! | O9: =HLOOKUP($G9,#REF!,$O$5,0)*$F9 -> #REF! | P9: =HLOOKUP($G9,#REF!,$P$5,0)*$F9 -> #REF! | R9: 11.59 | S9: 5.98
C10: =+(D10+E10)/2 -> 397.5 | D10: =+E9 -> 395 | E10: 400 | F10: =+E10-D10 -> 5 | G10: 2.5 | H10: =+R10*F10 -> 58.9 | I10: =+S10*F10 -> 30.05 | J10: =HLOOKUP($G10,#REF!,$J$5,1)*$F10 -> #REF! | K10: =HLOOKUP($G10,#REF!,$K$5,0)*$F10 -> #REF! | L10: =HLOOKUP($G10,#REF!,$L$5,0)*$F10 -> #REF! | M10: =HLOOKUP($G10,#REF!,$M$5,0)*$F10 -> #REF! | N10: =HLOOKUP($G10,#REF!,$N$5,0)*$F10 -> #REF! | O10: =HLOOKUP($G10,#REF!,$O$5,0)*$F10 -> #REF! | P10: =HLOOKUP($G10,#REF!,$P$5,0)*$F10 -> #REF! | R10: 11.78 | S10: 6.01
C11: =+(D11+E11)/2 -> 402.5 | D11: =+E10 -> 400 | E11: 405 | F11: =+E11-D11 -> 5 | G11: 2.5 | H11: =+R11*F11 -> 57.3 | I11: =+S11*F11 -> 30.05 | J11: =HLOOKUP($G11,#REF!,$J$5,1)*$F11 -> #REF! | K11: =HLOOKUP($G11,#REF!,$K$5,0)*$F11 -> #REF! | L11: =HLOOKUP($G11,#REF!,$L$5,0)*$F11 -> #REF! | M11: =HLOOKUP($G11,#REF!,$M$5,0)*$F11 -> #REF! | N11: =HLOOKUP($G11,#REF!,$N$5,0)*$F11 -> #REF! | O11: =HLOOKUP($G11,#REF!,$O$5,0)*$F11 -> #REF! | P11: =HLOOKUP($G11,#REF!,$P$5,0)*$F11 -> #REF! | R11: 11.46 | S11: 6.01
C12: =+(D12+E12)/2 -> 407.5 | D12: =+E11 -> 405 | E12: 410 | F12: =+E12-D12 -> 5 | G12: 2.5 | H12: =+R12*F12 -> 56 | I12: =+S12*F12 -> 26.55 | J12: =HLOOKUP($G12,#REF!,$J$5,1)*$F12 -> #REF! | K12: =HLOOKUP($G12,#REF!,$K$5,0)*$F12 -> #REF! | L12: =HLOOKUP($G12,#REF!,$L$5,0)*$F12 -> #REF! | M12: =HLOOKUP($G12,#REF!,$M$5,0)*$F12 -> #REF! | N12: =HLOOKUP($G12,#REF!,$N$5,0)*$F12 -> #REF! | O12: =HLOOKUP($G12,#REF!,$O$5,0)*$F12 -> #REF! | P12: =HLOOKUP($G12,#REF!,$P$5,0)*$F12 -> #REF! | R12: 11.2 | S12: 5.31
C13: =+(D13+E13)/2 -> 412.5 | D13: =+E12 -> 410 | E13: 415 | F13: =+E13-D13 -> 5 | G13: 2.5 | H13: =+R13*F13 -> 64.8 | I13: =+S13*F13 -> 29.85 | J13: =HLOOKUP($G13,#REF!,$J$5,1)*$F13 -> #REF! | K13: =HLOOKUP($G13,#REF!,$K$5,0)*$F13 -> #REF! | L13: =HLOOKUP($G13,#REF!,$L$5,0)*$F13 -> #REF! | M13: =HLOOKUP($G13,#REF!,$M$5,0)*$F13 -> #REF! | N13: =HLOOKUP($G13,#REF!,$N$5,0)*$F13 -> #REF! | O13: =HLOOKUP($G13,#REF!,$O$5,0)*$F13 -> #REF! | P13: =HLOOKUP($G13,#REF!,$P$5,0)*$F13 -> #REF! | R13: 12.96 | S13: 5.97
C14: =+(D14+E14)/2 -> 417.5 | D14: =+E13 -> 415 | E14: 420 | F14: =+E14-D14 -> 5 | G14: 2.5 | H14: =+R14*F14 -> 58.9 | I14: =+S14*F14 -> 27.05 | J14: =HLOOKUP($G14,#REF!,$J$5,1)*$F14 -> #REF! | K14: =HLOOKUP($G14,#REF!,$K$5,0)*$F14 -> #REF! | L14: =HLOOKUP($G14,#REF!,$L$5,0)*$F14 -> #REF! | M14: =HLOOKUP($G14,#REF!,$M$5,0)*$F14 -> #REF! | N14: =HLOOKUP($G14,#REF!,$N$5,0)*$F14 -> #REF! | O14: =HLOOKUP($G14,#REF!,$O$5,0)*$F14 -> #REF! | P14: =HLOOKUP($G14,#REF!,$P$5,0)*$F14 -> #REF! | R14: 11.78 | S14: 5.41
C15: =+(D15+E15)/2 -> 422.5 | D15: =+E14 -> 420 | E15: 425 | F15: =+E15-D15 -> 5 | G15: 2.5 | H15: =+R15*F15 -> 65.5 | I15: =+S15*F15 -> 30.05 | J15: =HLOOKUP($G15,#REF!,$J$5,1)*$F15 -> #REF! | K15: =HLOOKUP($G15,#REF!,$K$5,0)*$F15 -> #REF! | L15: =HLOOKUP($G15,#REF!,$L$5,0)*$F15 -> #REF! | M15: =HLOOKUP($G15,#REF!,$M$5,0)*$F15 -> #REF! | N15: =HLOOKUP($G15,#REF!,$N$5,0)*$F15 -> #REF! | O15: =HLOOKUP($G15,#REF!,$O$5,0)*$F15 -> #REF! | P15: =HLOOKUP($G15,#REF!,$P$5,0)*$F15 -> #REF! | R15: 13.1 | S15: 6.01
C16: =+(D16+E16)/2 -> 427.5 | D16: =+E15 -> 425 | E16: 430 | F16: =+E16-D16 -> 5 | G16: 2.5 | H16: =+R16*F16 -> 58.95 | I16: =+S16*F16 -> 30.05 | J16: =HLOOKUP($G16,#REF!,$J$5,1)*$F16 -> #REF! | K16: =HLOOKUP($G16,#REF!,$K$5,0)*$F16 -> #REF! | L16: =HLOOKUP($G16,#REF!,$L$5,0)*$F16 -> #REF! | M16: =HLOOKUP($G16,#REF!,$M$5,0)*$F16 -> #REF! | N16: =HLOOKUP($G16,#REF!,$N$5,0)*$F16 -> #REF! | O16: =HLOOKUP($G16,#REF!,$O$5,0)*$F16 -> #REF! | P16: =HLOOKUP($G16,#REF!,$P$5,0)*$F16 -> #REF! | R16: 11.79 | S16: 6.01
C17: =+(D17+E17)/2 -> 432.5 | D17: =+E16 -> 430 | E17: 435 | F17: =+E17-D17 -> 5 | G17: 2.5 | H17: =+R17*F17 -> 58.85 | I17: =+S17*F17 -> 30 | J17: =HLOOKUP($G17,#REF!,$J$5,1)*$F17 -> #REF! | K17: =HLOOKUP($G17,#REF!,$K$5,0)*$F17 -> #REF! | L17: =HLOOKUP($G17,#REF!,$L$5,0)*$F17 -> #REF! | M17: =HLOOKUP($G17,#REF!,$M$5,0)*$F17 -> #REF! | N17: =HLOOKUP($G17,#REF!,$N$5,0)*$F17 -> #REF! | O17: =HLOOKUP($G17,#REF!,$O$5,0)*$F17 -> #REF! | P17: =HLOOKUP($G17,#REF!,$P$5,0)*$F17 -> #REF! | R17: 11.77 | S17: 6
C18: =+(D18+E18)/2 -> 437.5 | D18: =+E17 -> 435 | E18: 440 | F18: =+E18-D18 -> 5 | G18: 3 | H18: =+R18*F18 -> 57.2 | I18: =+S18*F18 -> 38.35 | J18: =HLOOKUP($G18,#REF!,$J$5,1)*$F18 -> #REF! | K18: =HLOOKUP($G18,#REF!,$K$5,0)*$F18 -> #REF! | L18: =HLOOKUP($G18,#REF!,$L$5,0)*$F18 -> #REF! | M18: =HLOOKUP($G18,#REF!,$M$5,0)*$F18 -> #REF! | N18: =HLOOKUP($G18,#REF!,$N$5,0)*$F18 -> #REF! | O18: =HLOOKUP($G18,#REF!,$O$5,0)*$F18 -> #REF! | P18: =HLOOKUP($G18,#REF!,$P$5,0)*$F18 -> #REF! | R18: 11.44 | S18: 7.67
C19: =+(D19+E19)/2 -> 442.5 | D19: =+E18 -> 440 | E19: 445 | F19: =+E19-D19 -> 5 | G19: 4 | H19: =+R19*F19 -> 107.75 | I19: =+S19*F19 -> 65.25 | J19: =HLOOKUP($G19,#REF!,$J$5,1)*$F19 -> #REF! | K19: =HLOOKUP($G19,#REF!,$K$5,0)*$F19 -> #REF! | L19: =HLOOKUP($G19,#REF!,$L$5,0)*$F19 -> #REF! | M19: =HLOOKUP($G19,#REF!,$M$5,0)*$F19 -> #REF! | N19: =HLOOKUP($G19,#REF!,$N$5,0)*$F19 -> #REF! | O19: =HLOOKUP($G19,#REF!,$O$5,0)*$F19 -> #REF! | P19: =HLOOKUP($G19,#REF!,$P$5,0)*$F19 -> #REF! | R19: 21.55 | S19: 13.05
C20: =+(D20+E20)/2 -> 447.5 | D20: =+E19 -> 445 | E20: 450 | F20: =+E20-D20 -> 5 | G20: 7 | H20: =+R20*F20 -> 241 | I20: =+S20*F20 -> 176 | J20: =HLOOKUP($G20,#REF!,$J$5,1)*$F20 -> #REF! | K20: =HLOOKUP($G20,#REF!,$K$5,0)*$F20 -> #REF! | L20: =HLOOKUP($G20,#REF!,$L$5,0)*$F20 -> #REF! | M20: =HLOOKUP($G20,#REF!,$M$5,0)*$F20 -> #REF! | N20: =HLOOKUP($G20,#REF!,$N$5,0)*$F20 -> #REF! | O20: =HLOOKUP($G20,#REF!,$O$5,0)*$F20 -> #REF! | P20: =HLOOKUP($G20,#REF!,$P$5,0)*$F20 -> #REF! | R20: 48.2 | S20: 35.2
C21: =+(D21+E21)/2 -> 452.5 | D21: =+E20 -> 450 | E21: 455 | F21: =+E21-D21 -> 5 | G21: 7 | H21: =+R21*F21 -> 270.3 | I21: =+S21*F21 -> 201.65 | J21: =HLOOKUP($G21,#REF!,$J$5,1)*$F21 -> #REF! | K21: =HLOOKUP($G21,#REF!,$K$5,0)*$F21 -> #REF! | L21: =HLOOKUP($G21,#REF!,$L$5,0)*$F21 -> #REF! | M21: =HLOOKUP($G21,#REF!,$M$5,0)*$F21 -> #REF! | N21: =HLOOKUP($G21,#REF!,$N$5,0)*$F21 -> #REF! | O21: =HLOOKUP($G21,#REF!,$O$5,0)*$F21 -> #REF! | P21: =HLOOKUP($G21,#REF!,$P$5,0)*$F21 -> #REF! | R21: 54.06 | S21: 40.33
... C25: =+(D25+E25)/2 -> 468.5 | D25: =+E24 -> 467 | E25: 470 | F25: =+E25-D25 -> 3 | G25: 2.5 | H25: =+R25*F25 -> 42.33 | I25: =+S25*F25 -> 32.61 | J25: =HLOOKUP($G25,#REF!,$J$5,1)*$F25 -> #REF! | K25: =HLOOKUP($G25,#REF!,$K$5,0)*$F25 -> #REF! | L25: =HLOOKUP($G25,#REF!,$L$5,0)*$F25 -> #REF! | M25: =HLOOKUP($G25,#REF!,$M$5,0)*$F25 -> #REF! | N25: =HLOOKUP($G25,#REF!,$N$5,0)*$F25 -> #REF! | O25: =HLOOKUP($G25,#REF!,$O$5,0)*$F25 -> #REF! | P25: =HLOOKUP($G25,#REF!,$P$5,0)*$F25 -> #REF! | R25: 14.11 | S25: 10.87
G27: Total | H27: =+SUM(H9:H25) -> 2032.1989 | I27: =+SUM(I9:I25) -> 1257.8558 | J27: =+SUM(J9:J25) -> #REF! | K27: =+SUM(K9:K25) -> #REF! | L27: =+SUM(L9:L25) -> #REF! | M27: =+SUM(M9:M25) -> #REF! | N27: =+SUM(N9:N25) -> #REF! | O27: =+SUM(O9:O25) -> #REF! | P27: =+SUM(P9:P25) -> #REF!
J30: VOL | K30: RATIO | L30: ACERO/M | M30: L | N30: ACER
I31: MCA 2.5 | J31: 1.84 | K31: 30 | L31: =+J31*K31 -> 55.2 | M31: 5 | N31: =+L31*M31 -> 276 | O31: Kg
I32: MCA 3.0 | J32: 2.19 | K32: 30 | L32: =+J32*K32 -> 65.7 | M32: 5 | N32: =+L32*M32 -> 328.5
I33: MCA 4.0 | J33: 3.46 | K33: 35 | L33: =+J33*K33 -> 121.1 | M33: 5 | N33: =+L33*M33 -> 605.5
I34: MCA 7.0 | J34: 8.73 | K34: 65 | L34: =+J34*K34 -> 567.45 | M34: 5 | N34: =+L34*M34 -> 2837.25
